Workbook
Name DueDates: #REF!

Sheet Scoring Framework
D7: Rating | E7: Score | F7: Definition
D8: Does not address | E8: 1 | F8: Solution does not support or improve any major capabilities in this area
D9: Addresses minimal expectation | E9: 2 | F9: Minimaly meets expectation with some capabilities
D10: Meets basic expectation | E10: 3 | F10: Solution meets basic expectation but may require a cumbersome work-around
D11: Meets most of the expectation | E11: 4 | F11: Solution meets most of the expectation but may require a easy work-around
D12: Meets expectations | E12: 5 | F12: Solution meets expectations and/or improves major capabilities in this area

Sheet Architecture & Technology
A1: Architecture & Technology
C2: Date:
C3: Reviewer:
G4: =Summary!$I$6 -> Technology Solution 1 | J4: =Summary!$K$6 -> Technology Solution 2 | M4: =Summary!$M$6 -> Technology Solution 3 | P4: =Summary!$O$6 -> Technology Solution 4 | S4: =Summary!$Q$6 -> Technology Solution 5 | V4: =Summary!$S$6 -> Technology Solution 6
D5: Criteria | E5: Weight | G5: Score | H5: Comments | J5: Score | K5: Comments | M5: Score | N5: Comments | P5: Score | Q5: Comments | S5: Score | T5: Comments | V5: Score | W5: Comments
D6: =Summary!$D$16 -> User Experience & Design | E6: =Summary!$E$16 -> 0.1 | G6: =SUMPRODUCT(G7:G12,$E7:$E12) -> 0 | J6: =SUMPRODUCT(J7:J12,$E7:$E12) -> 0 | M6: =SUMPRODUCT(M7:M12,$E7:$E12) -> 0 | P6: =SUMPRODUCT(P7:P12,$E7:$E12) -> 0 | S6: =SUMPRODUCT(S7:S12,$E7:$E12) -> 0 | V6: =SUMPRODUCT(V7:V12,$E7:$E12) -> 0
D7: Describe how your solution provides support for omni-channel digital experiences (e.g., iFrame/Webview/Mashup, whitelabeling, external content management, deep-linking, search, and external profile/preference/consent management) | E7: =IF(Summary!$F$16=0,0,100%/Summary!$F$16) -> 0.2 | G7: 0 | J7: 0 | M7: 0 | P7: 0 | S7: 0 | V7: 0
D8: Describe how your solution supports a digital first approach, rendering on various mobile form factors and channels, including but not limited to: web, mobile app, IVR, chat/bot, conversational, SMS, push notifications, Extended Reality (Augemented Reality, Mixed Reality, Virtual Reality), wearables, other emerging digital channels | E8: =IF(Summary!$F$16=0,0,100%/Summary!$F$16) -> 0.2 | G8: 0 | J8: 0 | M8: 0 | P8: 0 | S8: 0 | V8: 0
D9: Describe the user research (e.g., interviews, surveys, usability tests) conducted to inform product design decisions, including with whom, at what stage of development, and how frequently the applicable research methods are applied. | E9: =IF(Summary!$F$16=0,0,100%/Summary!$F$16) -> 0.2 | G9: 0 | J9: 0 | M9: 0 | P9: 0 | S9: 0 | V9: 0
D10: What behavioral data or user analytics are used to measure user engagement and usability post launch? Will any of this data be accessible to our team to assess the digital tool’s performance and success? | E10: =IF(Summary!$F$16=0,0,100%/Summary!$F$16) -> 0.2 | G10: 0 | J10: 0 | M10: 0 | P10: 0 | S10: 0 | V10: 0
D11: Will your solution affect employee experience, roles, or work processes, and/or require detailed training? | G11: 0 | J11: 0 | M11: 0 | P11: 0 | S11: 0 | V11: 0
D12: What are your web & mobile development application platform? Describe any technology standards (including open-source) that you use. | E12: =IF(Summary!$F$16=0,0,100%/Summary!$F$16) -> 0.2 | G12: 0 | J12: 0 | M12: 0 | P12: 0 | S12: 0 | V12: 0
D13: =Summary!$D$17 -> Integration & Interoperability | E13: =Summary!$E$17 -> 0.1 | G13: =SUMPRODUCT(G14:G18,$E14:$E18) -> 0 | J13: =SUMPRODUCT(J14:J18,$E14:$E18) -> 0 | M13: =SUMPRODUCT(M14:M18,$E14:$E18) -> 0 | P13: =SUMPRODUCT(P14:P18,$E14:$E18) -> 0 | S13: =SUMPRODUCT(S14:S18,$E14:$E18) -> 0 | V13: =SUMPRODUCT(V14:V18,$E14:$E18) -> 0
D14: Describe how your solution supports the ability to integrate bulk data (ETL/ELT), streaming (realtime publishing/ingestion), and device telemetry. | E14: =IF(Summary!$F$17=0,0,100%/Summary!$F$17) -> 0.2 | G14: 0 | J14: 0 | M14: 0 | P14: 0 | S14: 0 | V14: 0
D15: Describe how your solution supports external data sharing with joint ventures (B2B beyond BSC). | E15: =IF(Summary!$F$17=0,0,100%/Summary!$F$17) -> 0.2 | G15: 0 | J15: 0 | M15: 0 | P15: 0 | S15: 0 | V15: 0
D16: Describe how your solution supports API based integration and what protocols are supported (e.g., FHIR, REST, SOAP, bulk data API, etc.) | E16: =IF(Summary!$F$17=0,0,100%/Summary!$F$17) -> 0.2 | G16: 0 | J16: 0 | M16: 0 | P16: 0 | S16: 0 | V16: 0
D17: Describe your support for integrated SSO (OIDC, SAML2.0). Identify what user roles the solution supports (e.g., administrators, developers, analysts, end users, etc.) and if that is a fixed or dynamic list. Also, identify what user access tools exist for managing the user roles and users. | E17: =IF(Summary!$F$17=0,0,100%/Summary!$F$17) -> 0.2 | G17: 0 | J17: 0 | M17: 0 | P17: 0 | S17: 0 | V17: 0
D18: Describe if and how your supports process integration (e.g., business process management, robotic process automation, personalization engine, etc.) | E18: =IF(Summary!$F$17=0,0,100%/Summary!$F$17) -> 0.2 | G18: 0 | J18: 0 | M18: 0 | P18: 0 | S18: 0 | V18: 0
D19: =Summary!$D$18 -> Security | E19: =Summary!$E$18 -> 0.2 | G19: =SUMPRODUCT(G20:G26,$E20:$E26) -> 0 | J19: =SUMPRODUCT(J20:J26,$E20:$E26) -> 0 | M19: =SUMPRODUCT(M20:M26,$E20:$E26) -> 0 | P19: =SUMPRODUCT(P20:P26,$E20:$E26) -> 0 | S19: =SUMPRODUCT(S20:S26,$E20:$E26) -> 0 | V19: =SUMPRODUCT(V20:V26,$E20:$E26) -> 0
D20: Describe how your solution is aligned to security standards (e.g., HIPAA/HITECH, O-Auth, PCI, PII, Identity & Access Management, etc.) and include the versions and levels supported of the standards. Additionaly, please provide a list of certifications you have achieved (e.g., SOC, ISO, FedRamp, etc.) | E20: =IF(Summary!$F$18=0,0,100%/Summary!$F$18) -> 0.14285714 | G20: 0 | J20: 0 | M20: 0 | P20: 0 | S20: 0 | V20: 0
D21: Does the Vendor have WTT (web tracking technologies) and does it capture or Collect PHI/PCI/PII; (If answer YES, VENDOR MUST SIGN A BAA** refer to legal) | E21: =IF(Summary!$F$18=0,0,100%/Summary!$F$18) -> 0.14285714 | G21: 0 | J21: 0 | M21: 0 | P21: 0 | S21: 0 | V21: 0
D22: Describe how your solution take into consideration secure coding practices and integrity of code repositories, including change management and access to these repositories, and open-source supply chain security | E22: =IF(Summary!$F$18=0,0,100%/Summary!$F$18) -> 0.14285714
D23: Describe how your solution ensures logging of and real time response to security events (as described in NIST standard) (e.g., SIEM/SOAR, suspicious user activity) and ability to provide these logs for monitoring purposes | E23: =IF(Summary!$F$18=0,0,100%/Summary!$F$18) -> 0.14285714
D24: Describe what systems hardening practices and audit controls put in place to ensure integrity of hardening | E24: =IF(Summary!$F$18=0,0,100%/Summary!$F$18) -> 0.14285714 | G24: 0 | J24: 0 | M24: 0 | P24: 0 | S24: 0 | V24: 0
D25: Describe support for protecting the data within your solution: [a] Encryption in motion and at rest [b] Role based access control (RBAC) including fine-grained access control (e.g., row-level, data classification, etc.) [c] If your solution supports multi-tenancy, describe how you segregate customer data [d] Describe support for Key Management (e.g. segregation, bring your own key) | E25: =IF(Summary!$F$18=0,0,100%/Summary!$F$18) -> 0.14285714 | G25: 0 | J25: 0 | M25: 0 | P25: 0 | S25: 0 | V25: 0
D26: Describe your support for advanced access controls (e.g., IP Whitelisting/Blacklisting, Zero-trust Initiatives, conditional access, etc.) | E26: =IF(Summary!$F$18=0,0,100%/Summary!$F$18) -> 0.14285714 | G26: 0 | J26: 0 | M26: 0 | P26: 0 | S26: 0 | V26: 0
D27: =Summary!$D$19 -> Architectural Alignment | E27: =Summary!$E$19 -> 0.1 | G27: =SUMPRODUCT(G28:G31,$E28:$E31) -> 0 | J27: =SUMPRODUCT(J28:J31,$E28:$E31) -> 0 | M27: =SUMPRODUCT(M28:M31,$E28:$E31) -> 0 | P27: =SUMPRODUCT(P28:P31,$E28:$E31) -> 0 | S27: =SUMPRODUCT(S28:S31,$E28:$E31) -> 0 | V27: =SUMPRODUCT(V28:V31,$E28:$E31) -> 0
D28: Describe how your solution can help simplify BSC's overall architecture to: [a] Support a Cloud first mindset [b] Support Hybrid, Private Cloud, and SaaS models of deployment [c] Implement Infrastructure as Code (IAC) [d] Support Container deployment (portability) and Serverless deployment (agility) [e] Automate provisioning and management of cloud resources via a CI/CD pipeline | E28: =IF(Summary!$F$19=0,0,100%/Summary!$F$19) -> 0.25 | G28: 0 | J28: 0 | M28: 0 | P28: 0 | S28: 0 | V28: 0
D29: To minimize business outage, describe how your solution provides a mature technology platform that: [a] Supports high availability & fault tolerance [b] Provides modular components that can scale (manual, dynamic) on demand of particular services vs the entire application [c] Scales storage, network, and users [d] Has business continuity [e] And enables Disaster Recovery | E29: =IF(Summary!$F$19=0,0,100%/Summary!$F$19) -> 0.25 | G29: 0 | J29: 0 | M29: 0 | P29: 0 | S29: 0 | V29: 0
D30: Describe your technology: [a] In support of meeting SLAs (e.g., response times, batch operation processing time, query/reporting time, etc.) [b] How the application and its processes are monitored [c] Data is archived [e] Support for non-production environments [f] What your KPI's are | E30: =IF(Summary!$F$19=0,0,100%/Summary!$F$19) -> 0.25 | G30: 0 | J30: 0 | M30: 0 | P30: 0 | S30: 0 | V30: 0
D31: Can you provide us a list of customers that are of the same size and nature as Blue Shield of California? | E31: =IF(Summary!$F$19=0,0,100%/Summary!$F$19) -> 0.25 | G31: 0 | J31: 0 | M31: 0 | P31: 0 | S31: 0 | V31: 0
D32: =Summary!$D$20 -> Implementation Timeline | E32: =Summary!$E$20 -> 0.1 | G32: =SUMPRODUCT(G33:G34,$E33:$E34) -> 0 | J32: =SUMPRODUCT(J33:J34,$E33:$E34) -> 0 | M32: =SUMPRODUCT(M33:M34,$E33:$E34) -> 0 | P32: =SUMPRODUCT(P33:P34,$E33:$E34) -> 0 | S32: =SUMPRODUCT(S33:S34,$E33:$E34) -> 0 | V32: =SUMPRODUCT(V33:V34,$E33:$E34) -> 0
D33: What are your policies and procedures to ensure the timeline to deploy is acceptable to the key stakeholders which includes product installation, configuration, and any potential custom work to enable the solution? | E33: =IF(Summary!$F$20=0,0,100%/Summary!$F$20) -> 0.5 | G33: 0 | J33: 0 | M33: 0 | P33: 0 | S33: 0 | V33: 0
D34: Does your solution enable a phased functionality implementation approach (example: data pipeline on product can be phased, iterated, agile)? | E34: =IF(Summary!$F$20=0,0,100%/Summary!$F$20) -> 0.5 | G34: 0 | J34: 0 | M34: 0 | P34: 0 | S34: 0 | V34: 0
D35: =Summary!$D$21 -> Data and Analytics | E35: =Summary!$E$21 -> 0.1 | G35: =SUMPRODUCT(G36:G41,$E36:$E41) -> 0 | J35: =SUMPRODUCT(J36:J41,$E36:$E41) -> 0 | M35: =SUMPRODUCT(M36:M41,$E36:$E41) -> 0 | P35: =SUMPRODUCT(P36:P41,$E36:$E41) -> 0 | S35: =SUMPRODUCT(S36:S41,$E36:$E41) -> 0 | V35: =SUMPRODUCT(V36:V41,$E36:$E41) -> 0
D36: Describe support for data management for both structured and non-structured data, including data lineage & traceability, data enrichment, integrated data repository, EMR, Claims, DNA, Fitness data, etc. [a] What is your support for batch file transfer ingres and egress? [b] What is your support for batch API (e.g., standard, HL7, FHIR)? [c] What is your support for Cloud data zero-copy or cloud-to-cloud? | E36: =IF(Summary!$F$21=0,0,100%/Summary!$F$21) -> 0.16666667 | G36: 0 | J36: 0 | M36: 0 | P36: 0 | S36: 0 | V36: 0
D37: Describe support for creating a structurally similar but inauthentic version of an organization's data that can be used for purposes such as software testing and user training | E37: =IF(Summary!$F$21=0,0,100%/Summary!$F$21) -> 0.16666667 | G37: 0 | J37: 0 | M37: 0 | P37: 0 | S37: 0 | V37: 0
D38: Describe support of data monitoring that provides the process of proactively reviewing and evaluating data and its quality to ensure that it is fit for purpose. The capability should support to measure and track the data using dashboards, alerts and reports. | E38: =IF(Summary!$F$21=0,0,100%/Summary!$F$21) -> 0.16666667 | G38: 0 | J38: 0 | M38: 0 | P38: 0 | S38: 0 | V38: 0
D39: Describe support for classifying data according to its business value and establish policies to migrate and store data on the appropriate storage tier and, ultimately, remove it altogether | E39: =IF(Summary!$F$21=0,0,100%/Summary!$F$21) -> 0.16666667 | G39: 0 | J39: 0 | M39: 0 | P39: 0 | S39: 0 | V39: 0
D40: Describe support for data quality management activities to ensure data accuracy, accessibility, comprehensiveness, consistency, currency, definition, granularity, precision, relevancy and timeliness. | E40: =IF(Summary!$F$21=0,0,100%/Summary!$F$21) -> 0.16666667 | G40: 0 | J40: 0 | M40: 0 | P40: 0 | S40: 0 | V40: 0
...

Sheet Vendor Functional
A1: Vendor Functional
C2: Date:
C3: Reviewer:
G4: =Summary!$I$6 -> Technology Solution 1 | J4: =Summary!$K$6 -> Technology Solution 2 | M4: =Summary!$M$6 -> Technology Solution 3 | P4: =Summary!$O$6 -> Technology Solution 4 | S4: =Summary!$Q$6 -> Technology Solution 5 | V4: =Summary!$S$6 -> Technology Solution 6
D5: Criteria | E5: Weight | G5: Score | H5: Comments | J5: Score | K5: Comments | M5: Score | N5: Comments | P5: Score | Q5: Comments | S5: Score | T5: Comments | V5: Score | W5: Comments
D6: =Summary!$D$27 -> Functional Category 1 | E6: =Summary!$E$27 -> 0.2 | G6: =SUMPRODUCT(G7:G10,$E7:$E10) -> 0 | J6: =SUMPRODUCT(J7:J10,$E7:$E10) -> 0 | M6: =SUMPRODUCT(M7:M10,$E7:$E10) -> 0 | P6: =SUMPRODUCT(P7:P10,$E7:$E10) -> 0 | S6: =SUMPRODUCT(S7:S10,$E7:$E10) -> 0 | V6: =SUMPRODUCT(V7:V10,$E7:$E10) -> 0
D7: Functional Category 1: Criteria 1 | E7: =IF(Summary!$F$27=0,0,100%/Summary!$F$27) -> 0.25 | G7: 0 | J7: 0 | M7: 0 | P7: 0 | S7: 0 | V7: 0
D8: Functional Category 1: Criteria 2 | E8: =IF(Summary!$F$27=0,0,100%/Summary!$F$27) -> 0.25 | G8: 0 | J8: 0 | M8: 0 | P8: 0 | S8: 0 | V8: 0
D9: Functional Category 1: Criteria 3 | E9: =IF(Summary!$F$27=0,0,100%/Summary!$F$27) -> 0.25 | G9: 0 | J9: 0 | M9: 0 | P9: 0 | S9: 0 | V9: 0
D10: Functional Category 1: Criteria 4 | E10: =IF(Summary!$F$27=0,0,100%/Summary!$F$27) -> 0.25 | G10: 0 | J10: 0 | M10: 0 | P10: 0 | S10: 0 | V10: 0
D11: =Summary!$D$28 -> Functional Category 2 | E11: =Summary!$E$28 -> 0.2 | G11: =SUMPRODUCT(G12:G15,$E12:$E15) -> 0 | J11: =SUMPRODUCT(J12:J15,$E12:$E15) -> 0 | M11: =SUMPRODUCT(M12:M15,$E12:$E15) -> 0 | P11: =SUMPRODUCT(P12:P15,$E12:$E15) -> 0 | S11: =SUMPRODUCT(S12:S15,$E12:$E15) -> 0 | V11: =SUMPRODUCT(V12:V15,$E12:$E15) -> 0
D12: Functional Category 2: Criteria 1 | E12: =IF(Summary!$F$28=0,0,100%/Summary!$F$28) -> 0.25 | G12: 0 | J12: 0 | M12: 0 | P12: 0 | S12: 0 | V12: 0
D13: Functional Category 2: Criteria 2 | E13: =IF(Summary!$F$28=0,0,100%/Summary!$F$28) -> 0.25 | G13: 0 | J13: 0 | M13: 0 | P13: 0 | S13: 0 | V13: 0
D14: Functional Category 2: Criteria 3 | E14: =IF(Summary!$F$28=0,0,100%/Summary!$F$28) -> 0.25 | G14: 0 | J14: 0 | M14: 0 | P14: 0 | S14: 0 | V14: 0
D15: Functional Category 2: Criteria 4 | E15: =IF(Summary!$F$28=0,0,100%/Summary!$F$28) -> 0.25 | G15: 0 | J15: 0 | M15: 0 | P15: 0 | S15: 0 | V15: 0
D16: =Summary!$D$29 -> Functional Category 3 | E16: =Summary!$E$29 -> 0.2 | G16: =SUMPRODUCT(G17:G20,$E17:$E20) -> 0 | J16: =SUMPRODUCT(J17:J20,$E17:$E20) -> 0 | M16: =SUMPRODUCT(M17:M20,$E17:$E20) -> 0 | P16: =SUMPRODUCT(P17:P20,$E17:$E20) -> 0 | S16: =SUMPRODUCT(S17:S20,$E17:$E20) -> 0 | V16: =SUMPRODUCT(V17:V20,$E17:$E20) -> 0
D17: Functional Category 3: Criteria 1 | E17: =IF(Summary!$F$29=0,0,100%/Summary!$F$29) -> 0.25 | G17: 0 | J17: 0 | M17: 0 | P17: 0 | S17: 0 | V17: 0
D18: Functional Category 3: Criteria 2 | E18: =IF(Summary!$F$29=0,0,100%/Summary!$F$29) -> 0.25 | G18: 0 | J18: 0 | M18: 0 | P18: 0 | S18: 0 | V18: 0
D19: Functional Category 3: Criteria 3 | E19: =IF(Summary!$F$29=0,0,100%/Summary!$F$29) -> 0.25 | G19: 0 | J19: 0 | M19: 0 | P19: 0 | S19: 0 | V19: 0
D20: Functional Category 3: Criteria 4 | E20: =IF(Summary!$F$29=0,0,100%/Summary!$F$29) -> 0.25 | G20: 0 | J20: 0 | M20: 0 | P20: 0 | S20: 0 | V20: 0
D21: =Summary!$D$30 -> Functional Category 4 | E21: =Summary!$E$30 -> 0.2 | G21: =SUMPRODUCT(G22:G25,$E22:$E25) -> 0 | J21: =SUMPRODUCT(J22:J25,$E22:$E25) -> 0 | M21: =SUMPRODUCT(M22:M25,$E22:$E25) -> 0 | P21: =SUMPRODUCT(P22:P25,$E22:$E25) -> 0 | S21: =SUMPRODUCT(S22:S25,$E22:$E25) -> 0 | V21: =SUMPRODUCT(V22:V25,$E22:$E25) -> 0
D22: Functional Category 4: Criteria 1 | E22: =IF(Summary!$F$30=0,0,100%/Summary!$F$30) -> 0.25 | G22: 0 | J22: 0 | M22: 0 | P22: 0 | S22: 0 | V22: 0
D23: Functional Category 4: Criteria 2 | E23: =IF(Summary!$F$30=0,0,100%/Summary!$F$30) -> 0.25 | G23: 0 | J23: 0 | M23: 0 | P23: 0 | S23: 0 | V23: 0
D24: Functional Category 4: Criteria 3 | E24: =IF(Summary!$F$30=0,0,100%/Summary!$F$30) -> 0.25 | G24: 0 | J24: 0 | M24: 0 | P24: 0 | S24: 0 | V24: 0
D25: Functional Category 4: Criteria 4 | E25: =IF(Summary!$F$30=0,0,100%/Summary!$F$30) -> 0.25 | G25: 0 | J25: 0 | M25: 0 | P25: 0 | S25: 0 | V25: 0
D26: =Summary!$D$31 -> Functional Category 5 | E26: =Summary!$E$31 -> 0.2 | G26: =SUMPRODUCT(G27:G30,$E27:$E30) -> 0 | J26: =SUMPRODUCT(J27:J30,$E27:$E30) -> 0 | M26: =SUMPRODUCT(M27:M30,$E27:$E30) -> 0 | P26: =SUMPRODUCT(P27:P30,$E27:$E30) -> 0 | S26: =SUMPRODUCT(S27:S30,$E27:$E30) -> 0 | V26: =SUMPRODUCT(V27:V30,$E27:$E30) -> 0
D27: Functional Category 5: Criteria 1 | E27: =IF(Summary!$F$31=0,0,100%/Summary!$F$31) -> 0.25 | G27: 0 | J27: 0 | M27: 0 | P27: 0 | S27: 0 | V27: 0
D28: Functional Category 5: Criteria 2 | E28: =IF(Summary!$F$31=0,0,100%/Summary!$F$31) -> 0.25 | G28: 0 | J28: 0 | M28: 0 | P28: 0 | S28: 0 | V28: 0
D29: Functional Category 5: Criteria 3 | E29: =IF(Summary!$F$31=0,0,100%/Summary!$F$31) -> 0.25 | G29: 0 | J29: 0 | M29: 0 | P29: 0 | S29: 0 | V29: 0
D30: Functional Category 5: Criteria 4 | E30: =IF(Summary!$F$31=0,0,100%/Summary!$F$31) -> 0.25 | G30: 0 | J30: 0 | M30: 0 | P30: 0 | S30: 0 | V30: 0
E32: =E6+E11+E16+E21+E26 -> 1 | G32: =(G6*$E6)+(G11*$E11)+(G16*$E16)+(G21*$E21)+(G26*$E26) -> 0 | J32: =(J6*$E6)+(J11*$E11)+(J16*$E16)+(J21*$E21)+(J26*$E26) -> 0 | M32: =(M6*$E6)+(M11*$E11)+(M16*$E16)+(M21*$E21)+(M26*$E26) -> 0 | P32: =(P6*$E6)+(P11*$E11)+(P16*$E16)+(P21*$E21)+(P26*$E26) -> 0 | S32: =(S6*$E6)+(S11*$E11)+(S16*$E16)+(S21*$E21)+(S26*$E26) -> 0 | V32: =(V6*$E6)+(V11*$E11)+(V16*$E16)+(V21*$E21)+(V26*$E26) -> 0
G53: ='Scoring Framework'!E8 -> 1 | J53: ='Scoring Framework'!I8 -> 0 | M53: ='Scoring Framework'!M8 -> 0 | P53: ='Scoring Framework'!Q8 -> 0 | S53: ='Scoring Framework'!U8 -> 0 | V53: ='Scoring Framework'!Y8 -> 0
G54: ='Scoring Framework'!E9 -> 2 | J54: ='Scoring Framework'!I9 -> 0 | M54: ='Scoring Framework'!M9 -> 0 | P54: ='Scoring Framework'!Q9 -> 0 | S54: ='Scoring Framework'!U9 -> 0 | V54: ='Scoring Framework'!Y9 -> 0
G55: ='Scoring Framework'!E12 -> 5 | J55: ='Scoring Framework'!I12 -> 0 | M55: ='Scoring Framework'!M12 -> 0 | P55: ='Scoring Framework'!Q12 -> 0 | S55: ='Scoring Framework'!U12 -> 0 | V55: ='Scoring Framework'!Y12 -> 0

Sheet Relative Cost
A1: Relative Cost
C2: Date:
C3: Reviewer:
G4: =Summary!$I$6 -> Technology Solution 1 | J4: =Summary!$K$6 -> Technology Solution 2 | M4: =Summary!$M$6 -> Technology Solution 3 | P4: =Summary!$O$6 -> Technology Solution 4 | S4: =Summary!$Q$6 -> Technology Solution 5 | V4: =Summary!$S$6 -> Technology Solution 6
D5: Criteria | E5: Weight | G5: Score | H5: Comments | J5: Score | K5: Comments | M5: Score | N5: Comments | P5: Score | Q5: Comments | S5: Score | T5: Comments | V5: Score | W5: Comments
D6: =Summary!$D$34 -> Efficiencies | E6: =Summary!$E$36 -> 0.3 | G6: =SUMPRODUCT(G7:G9,$E7:$E9) -> 0 | J6: =SUMPRODUCT(J7:J9,$E7:$E9) -> 0 | M6: =SUMPRODUCT(M7:M9,$E7:$E9) -> 0 | P6: =SUMPRODUCT(P7:P9,$E7:$E9) -> 0 | S6: =SUMPRODUCT(S7:S9,$E7:$E9) -> 0 | V6: =SUMPRODUCT(V7:V9,$E7:$E9) -> 0
D7: Anticipated platform procurement costs: see below | E7: =IF(Summary!$F$36=0,0,100%/Summary!$F$36) -> 0.33333333 | G7: 0 | J7: 0 | M7: 0 | P7: 0 | S7: 0 | V7: 0
D8: Anticipated professional services costs (vendor): see below | E8: =IF(Summary!$F$36=0,0,100%/Summary!$F$36) -> 0.33333333 | G8: 0 | J8: 0 | M8: 0 | P8: 0 | S8: 0 | V8: 0
D9: Other anticipated implementation costs (BSC business + IT) | E9: =IF(Summary!$F$36=0,0,100%/Summary!$F$36) -> 0.33333333 | G9: 0 | J9: 0 | M9: 0 | P9: 0 | S9: 0 | V9: 0
D10: =Summary!$D$35 -> Recurring Cost of Change | E10: =Summary!$E$35 -> 0.3 | G10: =SUMPRODUCT(G11:G13,$E11:$E13) -> 0 | J10: =SUMPRODUCT(J11:J13,$E11:$E13) -> 0 | M10: =SUMPRODUCT(M11:M13,$E11:$E13) -> 0 | P10: =SUMPRODUCT(P11:P13,$E11:$E13) -> 0 | S10: =SUMPRODUCT(S11:S13,$E11:$E13) -> 0 | V10: =SUMPRODUCT(V11:V13,$E11:$E13) -> 0
D11: Anticipated platform maintenance costs are less than or equivalent to current platform maintenance costs | E11: =IF(Summary!$F$35=0,0,100%/Summary!$F$35) -> 0.33333333 | G11: 0 | J11: 0 | M11: 0 | P11: 0 | S11: 0 | V11: 0
D12: Anticipated professional services are less than or equivalent to current professional services costs 6 months after implementation | E12: =IF(Summary!$F$35=0,0,100%/Summary!$F$35) -> 0.33333333 | G12: 0 | J12: 0 | M12: 0 | P12: 0 | S12: 0 | V12: 0
D13: Anticipated "other" maintenance costs are less than or equivalent to current software maintenance costs | E13: =IF(Summary!$F$35=0,0,100%/Summary!$F$35) -> 0.33333333 | G13: 0 | J13: 0 | M13: 0 | P13: 0 | S13: 0 | V13: 0
D14: =Summary!$D$36 -> Total Cost to Change | E14: =Summary!$E$34 -> 0.4 | G14: =SUMPRODUCT(G15:G16,$E15:$E16) -> 0 | J14: =SUMPRODUCT(J15:J16,$E15:$E16) -> 0 | M14: =SUMPRODUCT(M15:M16,$E15:$E16) -> 0 | P14: =SUMPRODUCT(P15:P16,$E15:$E16) -> 0 | S14: =SUMPRODUCT(S15:S16,$E15:$E16) -> 0 | V14: =SUMPRODUCT(V15:V16,$E15:$E16) -> 0
D15: Solution enables / aids component reuse to drive up efficiencies over time | E15: =IF(Summary!$F$34=0,0,100%/Summary!$F$34) -> 0.5 | G15: 0 | J15: 0 | M15: 0 | P15: 0 | S15: 0 | V15: 0
D16: Solution enables / aids productivity gains to drive up efficiencies over time | E16: =IF(Summary!$F$34=0,0,100%/Summary!$F$34) -> 0.5 | G16: 0 | J16: 0 | M16: 0 | P16: 0 | S16: 0 | V16: 0
E19: =E6+E10+E14 -> 1 | G19: =(G14*$E14)+(G10*$E10)+(G6*$E6) -> 0 | J19: =(J14*$E14)+(J10*$E10)+(J6*$E6) -> 0 | M19: =(M14*$E14)+(M10*$E10)+(M6*$E6) -> 0 | P19: =(P14*$E14)+(P10*$E10)+(P6*$E6) -> 0 | S19: =(S14*$E14)+(S10*$E10)+(S6*$E6) -> 0 | V19: =(V14*$E14)+(V10*$E10)+(V6*$E6) -> 0
D22: Compare the solutions against one another:
D23: * Most cost effective: 5
D24: * Next most cost effective: 3
D25: * Least cost effective: 1
G54: ='Scoring Framework'!E8 -> 1 | J54: ='Scoring Framework'!I8 -> 0 | M54: ='Scoring Framework'!M8 -> 0 | P54: ='Scoring Framework'!Q8 -> 0 | S54: ='Scoring Framework'!U8 -> 0 | V54: ='Scoring Framework'!Y8 -> 0
G55: ='Scoring Framework'!E9 -> 2 | J55: ='Scoring Framework'!I9 -> 0 | M55: ='Scoring Framework'!M9 -> 0 | P55: ='Scoring Framework'!Q9 -> 0 | S55: ='Scoring Framework'!U9 -> 0 | V55: ='Scoring Framework'!Y9 -> 0
G56: ='Scoring Framework'!E12 -> 5 | J56: ='Scoring Framework'!I12 -> 0 | M56: ='Scoring Framework'!M12 -> 0 | P56: ='Scoring Framework'!Q12 -> 0 | S56: ='Scoring Framework'!U12 -> 0 | V56: ='Scoring Framework'!Y12 -> 0

Sheet Hinge Factors
A1: Qualitative Hinge Factors
C2: Date:
C3: Reviewer:
G4: =Summary!$I$6 -> Technology Solution 1 | J4: =Summary!$K$6 -> Technology Solution 2 | M4: =Summary!$M$6 -> Technology Solution 3 | P4: =Summary!$O$6 -> Technology Solution 4 | S4: =Summary!$Q$6 -> Technology Solution 5 | V4: =Summary!$S$6 -> Technology Solution 6
D5: Criteria | E5: Weight | G5: Score | H5: Comments | J5: Score | K5: Comments | M5: Score | N5: Comments | P5: Score | Q5: Comments | S5: Score | T5: Comments | V5: Score | W5: Comments
D6: =Summary!$D$39 -> Expert Resource Availability | E6: =Summary!$E$39 -> 1 | G6: =SUMPRODUCT(G7:G8,$E7:$E8) -> 0 | J6: =SUMPRODUCT(J7:J8,$E7:$E8) -> 0 | M6: =SUMPRODUCT(M7:M8,$E7:$E8) -> 0 | P6: =SUMPRODUCT(P7:P8,$E7:$E8) -> 0 | S6: =SUMPRODUCT(S7:S8,$E7:$E8) -> 0 | V6: =SUMPRODUCT(V7:V8,$E7:$E8) -> 0
D7: Specialized resources required from vendors: (1 - significant; 3 - moderate; 5 - minimal) | E7: =IF(Summary!$F$39=0,0,100%/Summary!$F$39) -> 0.5 | G7: 0 | J7: 0 | M7: 0 | P7: 0 | S7: 0 | V7: 0
D8: Level of expertise required in-house: (1 - significant; 3 - moderate; 5 - minimal) | E8: =IF(Summary!$F$39=0,0,100%/Summary!$F$39) -> 0.5 | G8: 0 | J8: 0 | M8: 0 | P8: 0 | S8: 0 | V8: 0
D9: =Summary!$D$40 -> PLACEHOLDER 1 | E9: =Summary!$E$40 -> 0 | G9: =SUMPRODUCT(G10:G13,$E10:$E13) -> 0 | J9: =SUMPRODUCT(J10:J13,$E10:$E13) -> 0 | M9: =SUMPRODUCT(M10:M13,$E10:$E13) -> 0 | P9: =SUMPRODUCT(P10:P13,$E10:$E13) -> 0 | S9: =SUMPRODUCT(S10:S13,$E10:$E13) -> 0 | V9: =SUMPRODUCT(V10:V13,$E10:$E13) -> 0
E10: =IF(Summary!$F$40=0,0,100%/Summary!$F$40) -> 0 | G10: 0 | J10: 0 | M10: 0 | P10: 0 | S10: 0 | V10: 0
E11: =IF(Summary!$F$40=0,0,100%/Summary!$F$40) -> 0 | G11: 0 | J11: 0 | M11: 0 | P11: 0 | S11: 0 | V11: 0
E12: =IF(Summary!$F$40=0,0,100%/Summary!$F$40) -> 0 | G12: 0 | J12: 0 | M12: 0 | P12: 0 | S12: 0 | V12: 0
E13: =IF(Summary!$F$40=0,0,100%/Summary!$F$40) -> 0 | G13: 0 | J13: 0 | M13: 0 | P13: 0 | S13: 0 | V13: 0
D14: =Summary!$D$41 -> PLACEHOLDER 2 | E14: =Summary!$E$41 -> 0 | G14: =SUMPRODUCT(G15:G18,$E15:$E18) -> 0 | J14: =SUMPRODUCT(J15:J18,$E15:$E18) -> 0 | M14: =SUMPRODUCT(M15:M18,$E15:$E18) -> 0 | P14: =SUMPRODUCT(P15:P18,$E15:$E18) -> 0 | S14: =SUMPRODUCT(S15:S18,$E15:$E18) -> 0 | V14: =SUMPRODUCT(V15:V18,$E15:$E18) -> 0
E15: =IF(Summary!$F$41=0,0,100%/Summary!$F$41) -> 0 | G15: 0 | J15: 0 | M15: 0 | P15: 0 | S15: 0 | V15: 0
E16: =IF(Summary!$F$41=0,0,100%/Summary!$F$41) -> 0 | G16: 0 | J16: 0 | M16: 0 | P16: 0 | S16: 0 | V16: 0
E17: =IF(Summary!$F$41=0,0,100%/Summary!$F$41) -> 0 | G17: 0 | J17: 0 | M17: 0 | P17: 0 | S17: 0 | V17: 0
E18: =IF(Summary!$F$41=0,0,100%/Summary!$F$41) -> 0 | G18: 0 | J18: 0 | M18: 0 | P18: 0 | S18: 0 | V18: 0
D19: =Summary!$D$42 -> PLACEHOLDER 3 | E19: =Summary!$E$42 -> 0 | G19: =SUMPRODUCT(G20:G23,$E20:$E23) -> 0 | J19: =SUMPRODUCT(J20:J23,$E20:$E23) -> 0 | M19: =SUMPRODUCT(M20:M23,$E20:$E23) -> 0 | P19: =SUMPRODUCT(P20:P23,$E20:$E23) -> 0 | S19: =SUMPRODUCT(S20:S23,$E20:$E23) -> 0 | V19: =SUMPRODUCT(V20:V23,$E20:$E23) -> 0
E20: =IF(Summary!$F$42=0,0,100%/Summary!$F$42) -> 0 | G20: 0 | J20: 0 | M20: 0 | P20: 0 | S20: 0 | V20: 0
E21: =IF(Summary!$F$42=0,0,100%/Summary!$F$42) -> 0 | G21: 0 | J21: 0 | M21: 0 | P21: 0 | S21: 0 | V21: 0
E22: =IF(Summary!$F$42=0,0,100%/Summary!$F$42) -> 0 | G22: 0 | J22: 0 | M22: 0 | P22: 0 | S22: 0 | V22: 0
E23: =IF(Summary!$F$42=0,0,100%/Summary!$F$42) -> 0 | G23: 0 | J23: 0 | M23: 0 | P23: 0 | S23: 0 | V23: 0
E25: =E6+E9+E14+E19 -> 1 | G25: =(G14*$E14)+(G9*$E9)+(G19*$E19)+(G6*$E6) -> 0 | J25: =(J14*$E14)+(J9*$E9)+(J19*$E19)+(J6*$E6) -> 0 | M25: =(M14*$E14)+(M9*$E9)+(M19*$E19)+(M6*$E6) -> 0 | P25: =(P14*$E14)+(P9*$E9)+(P19*$E19)+(P6*$E6) -> 0 | S25: =(S14*$E14)+(S9*$E9)+(S19*$E19)+(S6*$E6) -> 0 | V25: =(V14*$E14)+(V9*$E9)+(V19*$E19)+(V6*$E6) -> 0
G43: ='Scoring Framework'!E8 -> 1 | J43: ='Scoring Framework'!I8 -> 0 | M43: ='Scoring Framework'!M8 -> 0 | P43: ='Scoring Framework'!Q8 -> 0 | S43: ='Scoring Framework'!U8 -> 0 | V43: ='Scoring Framework'!Y8 -> 0
G44: ='Scoring Framework'!E9 -> 2 | J44: ='Scoring Framework'!I9 -> 0 | M44: ='Scoring Framework'!M9 -> 0 | P44: ='Scoring Framework'!Q9 -> 0 | S44: ='Scoring Framework'!U9 -> 0 | V44: ='Scoring Framework'!Y9 -> 0
G45: ='Scoring Framework'!E12 -> 5 | J45: ='Scoring Framework'!I12 -> 0 | M45: ='Scoring Framework'!M12 -> 0 | P45: ='Scoring Framework'!Q12 -> 0 | S45: ='Scoring Framework'!U12 -> 0 | V45: ='Scoring Framework'!Y12 -> 0

Sheet Summary
B3: Summary Score
I6: Technology Solution 1 | K6: Technology Solution 2 | M6: Technology Solution 3 | O6: Technology Solution 4 | Q6: Technology Solution 5 | S6: Technology Solution 6
D7: Criteria | E7: Weight | F7: Max Score | I7: Avg. Score | J7: % of Max Score | K7: Avg. Score | L7: % of Max Score | M7: Avg. Score | N7: % of Max Score | O7: Avg. Score | P7: % of Max Score | Q7: Avg. Score | R7: % of Max Score | S7: Avg. Score | T7: % of Max Score
D8: Architecture & Technology | E8: 0.5 | F8: ='Scoring Framework'!$E$12 -> 5 | I8: ='Architecture & Technology'!G81 -> 0 | J8: =IF($F$8=0,0,I8/$F$8) -> 0 | K8: ='Architecture & Technology'!J81 -> 0 | L8: =IF($F$8=0,0,K8/$F$8) -> 0 | M8: ='Architecture & Technology'!M81 -> 0 | N8: =IF($F$8=0,0,M8/$F$8) -> 0 | O8: ='Architecture & Technology'!P81 -> 0 | P8: =IF($F$8=0,0,O8/$F$8) -> 0 | Q8: ='Architecture & Technology'!S81 -> 0 | R8: =IF($F$8=0,0,Q8/$F$8) -> 0 | S8: ='Architecture & Technology'!V81 -> 0 | T8: =IF($F$8=0,0,S8/$F$8) -> 0
D9: Platform Functional | E9: 0.3 | F9: ='Scoring Framework'!$E$12 -> 5 | I9: ='Vendor Functional'!G32 -> 0 | J9: =IF($F$9=0,0,I9/$F$9) -> 0 | K9: ='Vendor Functional'!J32 -> 0 | L9: =IF($F$9=0,0,K9/$F$9) -> 0 | M9: ='Vendor Functional'!M32 -> 0 | N9: =IF($F$9=0,0,M9/$F$9) -> 0 | O9: ='Vendor Functional'!P32 -> 0 | P9: =IF($F$9=0,0,O9/$F$9) -> 0 | Q9: ='Vendor Functional'!S32 -> 0 | R9: =IF($F$9=0,0,Q9/$F$9) -> 0 | S9: ='Vendor Functional'!V32 -> 0 | T9: =IF($F$9=0,0,S9/$F$9) -> 0
D10: Relative Cost | E10: 0.15 | F10: ='Scoring Framework'!$E$12 -> 5 | I10: ='Relative Cost'!G19 -> 0 | J10: =IF($F$10=0,0,I10/$F$10) -> 0 | K10: ='Relative Cost'!J19 -> 0 | L10: =IF($F$10=0,0,K10/$F$10) -> 0 | M10: ='Relative Cost'!M19 -> 0 | N10: =IF($F$10=0,0,M10/$F$10) -> 0 | O10: ='Relative Cost'!P19 -> 0 | P10: =IF($F$10=0,0,O10/$F$10) -> 0 | Q10: ='Relative Cost'!S19 -> 0 | R10: =IF($F$10=0,0,Q10/$F$10) -> 0 | S10: ='Relative Cost'!V19 -> 0 | T10: =IF($F$10=0,0,S10/$F$10) -> 0
D11: Hinge Factors | E11: 0.05 | F11: ='Scoring Framework'!$E$12 -> 5 | I11: ='Hinge Factors'!G25 -> 0 | J11: =IF($F$11=0,0,I11/$F$11) -> 0 | K11: ='Hinge Factors'!J25 -> 0 | L11: =IF($F$11=0,0,K11/$F$11) -> 0 | M11: ='Hinge Factors'!M25 -> 0 | N11: =IF($F$11=0,0,M11/$F$11) -> 0 | O11: ='Hinge Factors'!P25 -> 0 | P11: =IF($F$11=0,0,O11/$F$11) -> 0 | Q11: ='Hinge Factors'!S25 -> 0 | R11: =IF($F$11=0,0,Q11/$F$11) -> 0 | S11: ='Hinge Factors'!V25 -> 0 | T11: =IF($F$11=0,0,S11/$F$11) -> 0
E13: =SUM($E$8:$E$11) -> 1 | F13: 5 | I13: =SUMPRODUCT($E$8:$E$11,I8:I11) -> 0 | K13: =SUMPRODUCT($E$8:$E$11,K8:K11) -> 0 | M13: =SUMPRODUCT($E$8:$E$11,M8:M11) -> 0 | O13: =SUMPRODUCT($E$8:$E$11,O8:O11) -> 0 | Q13: =SUMPRODUCT($E$8:$E$11,Q8:Q11) -> 0 | S13: =SUMPRODUCT($E$8:$E$11,S8:S11) -> 0
D15: Architecture & Technology | E15: Weight | F15: Items
D16: User Experience & Design | E16: 0.1 | F16: 5
D17: Integration & Interoperability | E17: 0.1 | F17: 5
D18: Security | E18: 0.2 | F18: 7
D19: Architectural Alignment | E19: 0.1 | F19: 4
D20: Implementation Timeline | E20: 0.1 | F20: 2
D21: Data and Analytics | E21: 0.1 | F21: 6
D22: Artificial Intelligence & Machine Learning | E22: 0.1 | F22: 3
D23: Generative AI (Situational Criteria) | E23: 0.1 | F23: 24
D24: Service Management | E24: 0.1 | F24: 8
D26: Vendor Functional | E26: Weight | F26: Items
D27: Functional Category 1 | E27: 0.2 | F27: 4
D28: Functional Category 2 | E28: 0.2 | F28: 4
D29: Functional Category 3 | E29: 0.2 | F29: 4
D30: Functional Category 4 | E30: 0.2 | F30: 4
D31: Functional Category 5 | E31: 0.2 | F31: 4
D33: Relative Cost | E33: Weight | F33: Items
D34: Efficiencies | E34: 0.4 | F34: 2
D35: Recurring Cost of Change | E35: 0.3 | F35: 3
D36: Total Cost to Change | E36: 0.3 | F36: 3
D38: Qualitative "Hinge Factors" | E38: Weight | F38: Items
D39: Expert Resource Availability | E39: 1 | F39: 2
D40: PLACEHOLDER 1 | E40: 0 | F40: 0
D41: PLACEHOLDER 2 | E41: 0 | F41: 0
D42: PLACEHOLDER 3 | E42: 0 | F42: 0
